2022-06-07 14:13:59,191 ERROR: Exception on /reset_password_request [GET] [in C:\Python\projects\CoreCracker\venv\lib\site-packages\flask\app.py:1455]
Traceback (most recent call last):
  File "C:\Python\projects\CoreCracker\venv\lib\site-packages\flask\app.py", line 2077, in wsgi_app
    response = self.full_dispatch_request()
  File "C:\Python\projects\CoreCracker\venv\lib\site-packages\flask\app.py", line 1525, in full_dispatch_request
    rv = self.handle_user_exception(e)
  File "C:\Python\projects\CoreCracker\venv\lib\site-packages\flask\app.py", line 1523, in full_dispatch_request
    rv = self.dispatch_request()
  File "C:\Python\projects\CoreCracker\venv\lib\site-packages\flask\app.py", line 1509, in dispatch_request
    return self.ensure_sync(self.view_functions[rule.endpoint])(**req.view_args)
  File "C:\Python\projects\CoreCracker\app\routes.py", line 201, in reset_password_request
    return render_template('reset_password_request.html', title='Reset Password', form=form)
  File "C:\Python\projects\CoreCracker\venv\lib\site-packages\flask\templating.py", line 149, in render_template
    ctx.app.jinja_env.get_or_select_template(template_name_or_list),
  File "C:\Python\projects\CoreCracker\venv\lib\site-packages\jinja2\environment.py", line 1081, in get_or_select_template
    return self.get_template(template_name_or_list, parent, globals)
  File "C:\Python\projects\CoreCracker\venv\lib\site-packages\jinja2\environment.py", line 1010, in get_template
    return self._load_template(name, globals)
  File "C:\Python\projects\CoreCracker\venv\lib\site-packages\jinja2\environment.py", line 969, in _load_template
    template = self.loader.load(self, name, self.make_globals(globals))
  File "C:\Python\projects\CoreCracker\venv\lib\site-packages\jinja2\loaders.py", line 138, in load
    code = environment.compile(source, name, filename)
  File "C:\Python\projects\CoreCracker\venv\lib\site-packages\jinja2\environment.py", line 768, in compile
    self.handle_exception(source=source_hint)
  File "C:\Python\projects\CoreCracker\venv\lib\site-packages\jinja2\environment.py", line 936, in handle_exception
    raise rewrite_traceback_stack(source=source)
  File "C:\Python\projects\CoreCracker\app\templates\reset_password_request.html", line 1, in template
    {% extends.html %}
jinja2.exceptions.TemplateSyntaxError: unexpected '.'
2022-07-10 22:57:37,044 INFO: Microblog startup [in C:\Python\projects\CoreCracker\app\__init__.py:81]
2022-07-10 23:08:12,942 INFO: Corecracker startup [in C:\Python\projects\CoreCracker\app\__init__.py:81]
2022-07-10 23:09:33,361 INFO: Corecracker startup [in C:\Python\projects\CoreCracker\app\__init__.py:81]
2022-07-10 23:10:28,824 INFO: Corecracker startup [in C:\Python\projects\CoreCracker\app\__init__.py:81]
2022-07-10 23:14:37,958 INFO: Corecracker startup [in C:\Python\projects\CoreCracker\app\__init__.py:81]
2022-07-10 23:14:57,802 INFO: Corecracker startup [in C:\Python\projects\CoreCracker\app\__init__.py:81]
2022-07-10 23:15:04,568 INFO: Corecracker startup [in C:\Python\projects\CoreCracker\app\__init__.py:81]
2022-07-10 23:33:28,545 INFO: Corecracker startup [in C:\Python\projects\CoreCracker\app\__init__.py:84]
2022-07-10 23:45:48,763 INFO: Corecracker startup [in C:\Python\projects\CoreCracker\app\__init__.py:81]
2022-07-10 23:46:41,649 INFO: Corecracker startup [in C:\Python\projects\CoreCracker\app\__init__.py:81]
2022-07-10 23:47:14,336 INFO: Corecracker startup [in C:\Python\projects\CoreCracker\app\__init__.py:81]
2022-07-10 23:48:14,858 INFO: Corecracker startup [in C:\Python\projects\CoreCracker\app\__init__.py:81]
2022-07-11 09:54:11,300 ERROR: Exception on /utilization_hosts [POST] [in C:\Python\projects\CoreCracker\venv\lib\site-packages\flask\app.py:1455]
Traceback (most recent call last):
  File "C:\Python\projects\CoreCracker\venv\lib\site-packages\flask\app.py", line 2077, in wsgi_app
    response = self.full_dispatch_request()
  File "C:\Python\projects\CoreCracker\venv\lib\site-packages\flask\app.py", line 1525, in full_dispatch_request
    rv = self.handle_user_exception(e)
  File "C:\Python\projects\CoreCracker\venv\lib\site-packages\flask\app.py", line 1523, in full_dispatch_request
    rv = self.dispatch_request()
  File "C:\Python\projects\CoreCracker\venv\lib\site-packages\flask\app.py", line 1509, in dispatch_request
    return self.ensure_sync(self.view_functions[rule.endpoint])(**req.view_args)
  File "C:\Python\projects\CoreCracker\venv\lib\site-packages\flask_login\utils.py", line 303, in decorated_view
    return current_app.ensure_sync(func)(*args, **kwargs)
  File "C:\Python\projects\CoreCracker\app\routes.py", line 246, in utilization_hosts
    zabxDirn = parser.parsHosts(hosts, instance)
  File "C:\Python\projects\CoreCracker\app\parser.py", line 71, in parsHosts
    zabxDirn = zabxmax.uninUtilDirn(zabxDirn, inst)
  File "C:\Python\projects\CoreCracker\app\zabxmax.py", line 54, in uninUtilDirn
    intc_A, intc_B = parser.parsIntcItem(item['name'])   #получаем имена интерфейсов
  File "C:\Python\projects\CoreCracker\app\parser.py", line 86, in parsIntcItem
    return listIntc[0], listIntc[-1]
IndexError: list index out of range
2022-07-11 09:54:38,965 ERROR: Exception on /utilization_hosts [POST] [in C:\Python\projects\CoreCracker\venv\lib\site-packages\flask\app.py:1455]
Traceback (most recent call last):
  File "C:\Python\projects\CoreCracker\venv\lib\site-packages\flask\app.py", line 2077, in wsgi_app
    response = self.full_dispatch_request()
  File "C:\Python\projects\CoreCracker\venv\lib\site-packages\flask\app.py", line 1525, in full_dispatch_request
    rv = self.handle_user_exception(e)
  File "C:\Python\projects\CoreCracker\venv\lib\site-packages\flask\app.py", line 1523, in full_dispatch_request
    rv = self.dispatch_request()
  File "C:\Python\projects\CoreCracker\venv\lib\site-packages\flask\app.py", line 1509, in dispatch_request
    return self.ensure_sync(self.view_functions[rule.endpoint])(**req.view_args)
  File "C:\Python\projects\CoreCracker\venv\lib\site-packages\flask_login\utils.py", line 303, in decorated_view
    return current_app.ensure_sync(func)(*args, **kwargs)
  File "C:\Python\projects\CoreCracker\app\routes.py", line 246, in utilization_hosts
    zabxDirn = parser.parsHosts(hosts, instance)
  File "C:\Python\projects\CoreCracker\app\parser.py", line 71, in parsHosts
    zabxDirn = zabxmax.uninUtilDirn(zabxDirn, inst)
  File "C:\Python\projects\CoreCracker\app\zabxmax.py", line 54, in uninUtilDirn
    intc_A, intc_B = parser.parsIntcItem(item['name'])   #получаем имена интерфейсов
  File "C:\Python\projects\CoreCracker\app\parser.py", line 86, in parsIntcItem
    return listIntc[0], listIntc[-1]
IndexError: list index out of range
2022-07-11 09:55:12,354 ERROR: Exception on /utilization_hosts [POST] [in C:\Python\projects\CoreCracker\venv\lib\site-packages\flask\app.py:1455]
Traceback (most recent call last):
  File "C:\Python\projects\CoreCracker\venv\lib\site-packages\flask\app.py", line 2077, in wsgi_app
    response = self.full_dispatch_request()
  File "C:\Python\projects\CoreCracker\venv\lib\site-packages\flask\app.py", line 1525, in full_dispatch_request
    rv = self.handle_user_exception(e)
  File "C:\Python\projects\CoreCracker\venv\lib\site-packages\flask\app.py", line 1523, in full_dispatch_request
    rv = self.dispatch_request()
  File "C:\Python\projects\CoreCracker\venv\lib\site-packages\flask\app.py", line 1509, in dispatch_request
    return self.ensure_sync(self.view_functions[rule.endpoint])(**req.view_args)
  File "C:\Python\projects\CoreCracker\venv\lib\site-packages\flask_login\utils.py", line 303, in decorated_view
    return current_app.ensure_sync(func)(*args, **kwargs)
  File "C:\Python\projects\CoreCracker\app\routes.py", line 246, in utilization_hosts
    zabxDirn = parser.parsHosts(hosts, instance)
  File "C:\Python\projects\CoreCracker\app\parser.py", line 71, in parsHosts
    zabxDirn = zabxmax.uninUtilDirn(zabxDirn, inst)
  File "C:\Python\projects\CoreCracker\app\zabxmax.py", line 54, in uninUtilDirn
    intc_A, intc_B = parser.parsIntcItem(item['name'])   #получаем имена интерфейсов
  File "C:\Python\projects\CoreCracker\app\parser.py", line 86, in parsIntcItem
    return listIntc[0], listIntc[-1]
IndexError: list index out of range
2022-07-11 09:56:01,004 ERROR: Exception on /utilization_hosts [POST] [in C:\Python\projects\CoreCracker\venv\lib\site-packages\flask\app.py:1455]
Traceback (most recent call last):
  File "C:\Python\projects\CoreCracker\venv\lib\site-packages\flask\app.py", line 2077, in wsgi_app
    response = self.full_dispatch_request()
  File "C:\Python\projects\CoreCracker\venv\lib\site-packages\flask\app.py", line 1525, in full_dispatch_request
    rv = self.handle_user_exception(e)
  File "C:\Python\projects\CoreCracker\venv\lib\site-packages\flask\app.py", line 1523, in full_dispatch_request
    rv = self.dispatch_request()
  File "C:\Python\projects\CoreCracker\venv\lib\site-packages\flask\app.py", line 1509, in dispatch_request
    return self.ensure_sync(self.view_functions[rule.endpoint])(**req.view_args)
  File "C:\Python\projects\CoreCracker\venv\lib\site-packages\flask_login\utils.py", line 303, in decorated_view
    return current_app.ensure_sync(func)(*args, **kwargs)
  File "C:\Python\projects\CoreCracker\app\routes.py", line 246, in utilization_hosts
    zabxDirn = parser.parsHosts(hosts, instance)
  File "C:\Python\projects\CoreCracker\app\parser.py", line 71, in parsHosts
    zabxDirn = zabxmax.uninUtilDirn(zabxDirn, inst)
  File "C:\Python\projects\CoreCracker\app\zabxmax.py", line 54, in uninUtilDirn
    intc_A, intc_B = parser.parsIntcItem(item['name'])   #получаем имена интерфейсов
  File "C:\Python\projects\CoreCracker\app\parser.py", line 86, in parsIntcItem
    return listIntc[0], listIntc[-1]
IndexError: list index out of range
